{
 "cells": [
  {
   "cell_type": "markdown",
   "metadata": {},
   "source": [
    "# Грешки и изключения (Error and exceptions)\n",
    "\n",
    "Понякога се случват неща, които не очакваме, или програмата ни влиза в състояние, което е грешно или пък е с недефинирано поведение. Например, ако се опитаме да отворим файл, който не съществува, или ако се опитаме да разделим число на 0 и т.н. Ако такава \"грешка\" е фатална, то е редно програмата да спре изпълнението си, съобщавайки за това с някаъв вид програмна грешка (error). Ако не е толкова фатална, например е просто специален случай, който можем да третираме по по-различен начин, то това наричаме \"изключение\" (exception). Ние като програмисти не е редно да \"хващаме\" и обработваме грешките, а само изключенията."
   ]
  },
  {
   "cell_type": "markdown",
   "metadata": {},
   "source": [
    "## (Синтактични) Грешки\n",
    "\n",
    "В Python грешките биват единствено синтактични - от тип `SyntaxError`. Тази грешка се хвърля когато Python parser-a забележи синтектичен проблем в кода, което би довело до невъзможността му за изпълнение."
   ]
  },
  {
   "cell_type": "code",
   "execution_count": 2,
   "metadata": {},
   "outputs": [
    {
     "ename": "SyntaxError",
     "evalue": "incomplete input (1478308394.py, line 1)",
     "output_type": "error",
     "traceback": [
      "\u001b[0;36m  Cell \u001b[0;32mIn [2], line 1\u001b[0;36m\u001b[0m\n\u001b[0;31m    print((\"I like brackets\")\u001b[0m\n\u001b[0m                             ^\u001b[0m\n\u001b[0;31mSyntaxError\u001b[0m\u001b[0;31m:\u001b[0m incomplete input\n"
     ]
    }
   ],
   "source": [
    "print((\"I like brackets\")"
   ]
  },
  {
   "cell_type": "markdown",
   "metadata": {},
   "source": [
    "## Изключения"
   ]
  },
  {
   "cell_type": "markdown",
   "metadata": {},
   "source": [
    "Дори и кодът да е синтактично правилен обаче, изпълнението му е възможно да доведе до грешка. Такива грешки, които се засичат по време на изпълнението на програмата се наричат \"изключения\" (exceptions) и е възможно да бъдат \"хванати\" и обработени по желан от нас начин. Примери за често-срещани изключения:"
   ]
  },
  {
   "cell_type": "code",
   "execution_count": 8,
   "metadata": {},
   "outputs": [
    {
     "ename": "ZeroDivisionError",
     "evalue": "division by zero",
     "output_type": "error",
     "traceback": [
      "\u001b[0;31m---------------------------------------------------------------------------\u001b[0m",
      "\u001b[0;31mZeroDivisionError\u001b[0m                         Traceback (most recent call last)",
      "Cell \u001b[0;32mIn [8], line 1\u001b[0m\n\u001b[0;32m----> 1\u001b[0m \u001b[39m42\u001b[39m \u001b[39m/\u001b[39m \u001b[39m0\u001b[39m\n",
      "\u001b[0;31mZeroDivisionError\u001b[0m: division by zero"
     ]
    }
   ],
   "source": [
    "42 / 0"
   ]
  },
  {
   "cell_type": "code",
   "execution_count": 5,
   "metadata": {},
   "outputs": [
    {
     "ename": "NameError",
     "evalue": "name 'name_of_crush' is not defined",
     "output_type": "error",
     "traceback": [
      "\u001b[0;31m---------------------------------------------------------------------------\u001b[0m",
      "\u001b[0;31mNameError\u001b[0m                                 Traceback (most recent call last)",
      "Cell \u001b[0;32mIn [5], line 1\u001b[0m\n\u001b[0;32m----> 1\u001b[0m \u001b[39m\"\u001b[39m\u001b[39mI love \u001b[39m\u001b[39m\"\u001b[39m \u001b[39m+\u001b[39m name_of_crush\n",
      "\u001b[0;31mNameError\u001b[0m: name 'name_of_crush' is not defined"
     ]
    }
   ],
   "source": [
    "\"I love \" + name_of_crush"
   ]
  },
  {
   "cell_type": "code",
   "execution_count": 6,
   "metadata": {},
   "outputs": [
    {
     "ename": "TypeError",
     "evalue": "can only concatenate str (not \"int\") to str",
     "output_type": "error",
     "traceback": [
      "\u001b[0;31m---------------------------------------------------------------------------\u001b[0m",
      "\u001b[0;31mTypeError\u001b[0m                                 Traceback (most recent call last)",
      "Cell \u001b[0;32mIn [6], line 1\u001b[0m\n\u001b[0;32m----> 1\u001b[0m \u001b[39m\"\u001b[39m\u001b[39m1\u001b[39m\u001b[39m\"\u001b[39m \u001b[39m+\u001b[39m \u001b[39m1\u001b[39m\n",
      "\u001b[0;31mTypeError\u001b[0m: can only concatenate str (not \"int\") to str"
     ]
    }
   ],
   "source": [
    "\"1\" + 1"
   ]
  },
  {
   "cell_type": "markdown",
   "metadata": {},
   "source": [
    "*Note:* въпреки, че са всъщност exceptions, а не errors, имената на доста вградени изключения завършват на `Error` в Python."
   ]
  },
  {
   "cell_type": "markdown",
   "metadata": {},
   "source": [
    "## Хващане на изключения"
   ]
  },
  {
   "cell_type": "markdown",
   "metadata": {},
   "source": [
    "С `try-except` конструкцията можем да хванем изключение при изпълнение на даден код и да извършим някакво действие, ако се случи такова. В `try` блокът се слага кодът, който искаме да изпълним, а в `except` блокът - кодът, който искаме да се изпълни, ако се случи изключение. При хващане на изключение програмата не се терминира, а продължава изпълнението си след `try-except` конструкцията."
   ]
  },
  {
   "cell_type": "code",
   "execution_count": 12,
   "metadata": {},
   "outputs": [
    {
     "name": "stdout",
     "output_type": "stream",
     "text": [
      "Sorry bro, that's not a valid number. Try again...\n",
      "Sorry bro, that's not a valid number. Try again...\n",
      "You entered:  124\n"
     ]
    }
   ],
   "source": [
    "while True:\n",
    "    try:\n",
    "        x = int(input(\"Please enter a number: \"))\n",
    "        print(\"You entered: \", x)\n",
    "        break\n",
    "    except ValueError:\n",
    "        print(\"Sorry bro, that's not a valid number. Try again...\")"
   ]
  },
  {
   "cell_type": "markdown",
   "metadata": {},
   "source": [
    "Забележете, че можем да укажем изрично типа на изключението, което искаме да хванем, като аргумент на `except` блока. В горният пример искаме да хванем единствено изключения от тип `ValueError`, т.е. проблеми с въведената стойност. Така позволяваме на потребителят например да приключи изпълнението на програмата с Ctrl+C (или подобен метод), понеже това действие би хвърлило `KeyboardInterrupt` изключение."
   ]
  },
  {
   "cell_type": "markdown",
   "metadata": {},
   "source": [
    "Можем естествено и да не укажем тип, а да хванем абсолютно всички възможни изключения:"
   ]
  },
  {
   "cell_type": "code",
   "execution_count": 16,
   "metadata": {},
   "outputs": [],
   "source": [
    "try:\n",
    "    risky_func()\n",
    "except:\n",
    "    pass  # never ever do this, for the sake of humanity"
   ]
  },
  {
   "cell_type": "markdown",
   "metadata": {},
   "source": [
    "Много коварен antipattern обаче е обграждането на проблематичен код с `except` блок, който е празен. Повече по темата: https://realpython.com/the-most-diabolical-python-antipattern/"
   ]
  },
  {
   "cell_type": "markdown",
   "metadata": {},
   "source": [
    "Вместо това, може например да логнем грешката в някой файл или на стандартния изход (или по-добре от STDOUT - в STDERR, но в примера ще използваме STDOUT с цел простота):"
   ]
  },
  {
   "cell_type": "code",
   "execution_count": 20,
   "metadata": {},
   "outputs": [
    {
     "name": "stdout",
     "output_type": "stream",
     "text": [
      "name 'risky_func' is not defined\n"
     ]
    }
   ],
   "source": [
    "import sys\n",
    "\n",
    "try:\n",
    "    risky_func()\n",
    "except Exception as e:\n",
    "    print(e)"
   ]
  },
  {
   "cell_type": "markdown",
   "metadata": {},
   "source": [
    "Както се вижда от примера, можем да присвоим изключението към променлива, която да използваме в `except` блока. Това е полезно ако искаме да използваме изключението или аргументите на изключението, които се намират в `args` атрибута на всяко изключение."
   ]
  },
  {
   "cell_type": "code",
   "execution_count": 21,
   "metadata": {},
   "outputs": [
    {
     "name": "stdout",
     "output_type": "stream",
     "text": [
      "name 'risky_func' is not defined\n",
      "(\"name 'risky_func' is not defined\",)\n"
     ]
    }
   ],
   "source": [
    "try:\n",
    "    risky_func()\n",
    "except Exception as e:\n",
    "    print(e)\n",
    "    print(e.args)"
   ]
  },
  {
   "cell_type": "markdown",
   "metadata": {},
   "source": [
    "Можем да очакваме повече от един тип изключения по няколко начина:"
   ]
  },
  {
   "cell_type": "code",
   "execution_count": 39,
   "metadata": {},
   "outputs": [
    {
     "name": "stdout",
     "output_type": "stream",
     "text": [
      "Division by zero.\n",
      "Oops:  division by zero\n"
     ]
    }
   ],
   "source": [
    "def f(): return 42\n",
    "def g(): return 0\n",
    "\n",
    "try:\n",
    "    # f()[2]    # uncomment for third error\n",
    "    # y = h()  # uncomment for second error\n",
    "    y = f() / g()\n",
    "except ZeroDivisionError:\n",
    "    print(\"Division by zero.\")\n",
    "except NameError as e:\n",
    "    print(\"Name error: \", e)\n",
    "except Exception as e:\n",
    "    print(\"Other error: \", e)\n",
    "\n",
    "try:\n",
    "    y = f() / g() + h()\n",
    "except (ZeroDivisionError, NameError) as e:\n",
    "    print(\"Oops: \", e)"
   ]
  },
  {
   "cell_type": "markdown",
   "metadata": {},
   "source": [
    "## Хвърляне на изключения"
   ]
  },
  {
   "cell_type": "markdown",
   "metadata": {},
   "source": [
    "`assert`"
   ]
  }
 ],
 "metadata": {
  "kernelspec": {
   "display_name": "Python 3.10.6 64-bit",
   "language": "python",
   "name": "python3"
  },
  "language_info": {
   "codemirror_mode": {
    "name": "ipython",
    "version": 3
   },
   "file_extension": ".py",
   "mimetype": "text/x-python",
   "name": "python",
   "nbconvert_exporter": "python",
   "pygments_lexer": "ipython3",
   "version": "3.10.6"
  },
  "orig_nbformat": 4,
  "vscode": {
   "interpreter": {
    "hash": "b0fa6594d8f4cbf19f97940f81e996739fb7646882a419484c72d19e05852a7e"
   }
  }
 },
 "nbformat": 4,
 "nbformat_minor": 2
}
